2025-02-12 19:08:27,663 - client - ERROR - Error handling received message: Display error
Traceback (most recent call last):
  File "/Users/bjwang/Documents/Distributed Programming/wire-protocols/client/client.py", line 187, in handle_received_message
    self.gui.display_message(message_data)
  File "/opt/miniconda3/lib/python3.12/unittest/mock.py", line 1139, in __call__
    return self._mock_call(*args, **kwargs)
           ^^^^^^^^^^^^^^^^^^^^^^^^^^^^^^^^
  File "/opt/miniconda3/lib/python3.12/unittest/mock.py", line 1143, in _mock_call
    return self._execute_mock_call(*args, **kwargs)
           ^^^^^^^^^^^^^^^^^^^^^^^^^^^^^^^^^^^^^^^^
  File "/opt/miniconda3/lib/python3.12/unittest/mock.py", line 1198, in _execute_mock_call
    raise effect
Exception: Display error
Traceback (most recent call last):
  File "/Users/bjwang/Documents/Distributed Programming/wire-protocols/client/client.py", line 187, in handle_received_message
    self.gui.display_message(message_data)
  File "/opt/miniconda3/lib/python3.12/unittest/mock.py", line 1139, in __call__
    return self._mock_call(*args, **kwargs)
           ^^^^^^^^^^^^^^^^^^^^^^^^^^^^^^^^
  File "/opt/miniconda3/lib/python3.12/unittest/mock.py", line 1143, in _mock_call
    return self._execute_mock_call(*args, **kwargs)
           ^^^^^^^^^^^^^^^^^^^^^^^^^^^^^^^^^^^^^^^^
  File "/opt/miniconda3/lib/python3.12/unittest/mock.py", line 1198, in _execute_mock_call
    raise effect
Exception: Display error

2025-02-12 19:08:27,671 - client - ERROR - Error updating recent chats: Update error
Traceback (most recent call last):
  File "/Users/bjwang/Documents/Distributed Programming/wire-protocols/client/client.py", line 198, in update_recent_chats
    self.gui.update_recent_chats(chats_data['chats'], chats_data['total_pages'])
  File "/opt/miniconda3/lib/python3.12/unittest/mock.py", line 1139, in __call__
    return self._mock_call(*args, **kwargs)
           ^^^^^^^^^^^^^^^^^^^^^^^^^^^^^^^^
  File "/opt/miniconda3/lib/python3.12/unittest/mock.py", line 1143, in _mock_call
    return self._execute_mock_call(*args, **kwargs)
           ^^^^^^^^^^^^^^^^^^^^^^^^^^^^^^^^^^^^^^^^
  File "/opt/miniconda3/lib/python3.12/unittest/mock.py", line 1198, in _execute_mock_call
    raise effect
Exception: Update error
Traceback (most recent call last):
  File "/Users/bjwang/Documents/Distributed Programming/wire-protocols/client/client.py", line 198, in update_recent_chats
    self.gui.update_recent_chats(chats_data['chats'], chats_data['total_pages'])
  File "/opt/miniconda3/lib/python3.12/unittest/mock.py", line 1139, in __call__
    return self._mock_call(*args, **kwargs)
           ^^^^^^^^^^^^^^^^^^^^^^^^^^^^^^^^
  File "/opt/miniconda3/lib/python3.12/unittest/mock.py", line 1143, in _mock_call
    return self._execute_mock_call(*args, **kwargs)
           ^^^^^^^^^^^^^^^^^^^^^^^^^^^^^^^^^^^^^^^^
  File "/opt/miniconda3/lib/python3.12/unittest/mock.py", line 1198, in _execute_mock_call
    raise effect
Exception: Update error

